Workbook

Sheet Master
B1: Sted | C1: Overskudd | D1: ut | E1: inn | G1: Feilsøking | Q1: Drottningborgrussen | X1: Ikke kategoriserte utgifter
B2: Startkapital 01.08.25 | C2: 42648 | G2: kategori | H2: Diff | Q2: Intekter | R2: =SUM(R4:R33) -> 3240
B3: Gammelt skyldig (sommertreff) | C3: =E3+D3 -> -39403 | D3: -39403 | G3: Inn kiosk | H3: ='Inn Kiosk'!B77 -> 128188.24 | N3: Intektsforklaringer | Q3: Utført dato | R3: Beløp inn | S3: Mottakernavn | T3: Numref | U3: Melding/KID/Fakt.nr | X3: Intekter | Y3: =SUM(Y6:Y260) -> 6455 | AC3: Brukt | AD3: Utgifter | AE3: =SUM(AE4:AE35) -> -1672.75
B4: Misjonsprojekt | C4: =E4+D4 -> -1357943 | D4: -1357943 | G4: Vipps | H4: ='Vippsutskrifter+ Kiosk'!B68 -> #REF! | N4: Volley | O4: -8175 | Q4: 30.09.2025 | R4: 185 | S4: Drottningborgrussen | T4: 606892 | U4: Utb. 2000689 Vippsnr 115851
B5: Lån drottningborg | C5: =E5+D5 -> 264 | E5: 264 | G5: Terminal | H5: =Terminalutskrifter!B67 -> -2705 | N5: nattcup | O5: -900 | Q5: 29.09.2025 | R5: 190 | S5: Drottningborgrussen | T5: 476321 | U5: Utb. 2000688 Vippsnr 115851 | X5: Utført dato | Y5: Beløp inn | Z5: Mottakernavn | AA5: Numref | AB5: Melding/KID/Fakt.nr | AD5: Utført dato | AE5: Beløp ut | AF5: Mottakernavn | AG5: Numref | AH5: Melding/KID/Fakt.nr
G6: Kjøre | H6: =Kjøregodtgjørelse!U2 -> 0 | Q6: 28.10.2025 | R6: 37 | S6: Drottningborgrussen | T6: 941095 | U6: Utb. 2000697 Vippsnr 115851 | X6: 13.10.2025 | Y6: 161 | Z6: Kredinor AS | AB6: STØ AS
B7: kiosk | C7: =E7+D7 -> -111553.24 | D7: ='Inn Kiosk'!B76 -> -128188.24 | E7: ='Vippsutskrifter+ Kiosk'!B67+Terminalutskrifter!B66 -> 16635 | G7: kvitering | H7: ='Inn Kiosk'!C71 -> 0 | N7: Total forklart | O7: =SUM(O4:O5) -> -9075 | Q7: 26.09.2025 | R7: 193 | S7: Drottningborgrussen | T7: 393270 | U7: Utb. 2000687 Vippsnr 115851 | X7: 14.08.2025 | Y7: 283 | Z7: Drottningborgrussen | AA7: 254875 | AB7: Utb. 2000024 Vippsnr 126054
B8: Isruss | C8: =E8+D8 -> -2817.85 | D8: =Isruss!D4 -> -3917.85 | E8: =Isruss!D5 -> 1100 | N8: Total bank | O8: =SUM(R3:R26) -> 3240 | Q8: 22.09.2025 | R8: 200 | S8: Drottningborgrussen | T8: 1526097 | U8: Utb. 2000686 Vippsnr 115851 | X8: 15.08.2025 | Y8: 280 | AA8: 82802400000 | AB8: NettBedrift betalingsformidling
B9: Milkshake | C9: =E9+D9 -> -5457.89 | D9: =Milkshake!D4 -> -6475.89 | E9: =Milkshake!D5 -> 1018 | N9: Ukjent | O9: =O8+O7 -> -5835 | Q9: 21.10.2025 | R9: 101 | S9: Drottningborgrussen | T9: 517802 | U9: Utb. 2000696 Vippsnr 115851 | X9: 15.09.2025 | Y9: 232 | Z9: Kredinor AS | AB9: STØ AS
B10: Pant | C10: =E10+D10 -> 261 | D10: 0 | E10: =Panteruss!D5 -> 261 | Q10: 19.09.2025 | R10: 205 | S10: Drottningborgrussen | T10: 1451306 | U10: Utb. 2000685 Vippsnr 115851 | X10: 16.10.2025 | Y10: 138 | Z10: Drottningborgrussen | AA10: 8016934193
B11: Basar | C11: =E11+D11 -> 428 | E11: =Basar!E5 -> 428 | Q11: 17.09.2025 | R11: 217 | S11: Drottningborgrussen | T11: 1275771 | U11: Utb. 2000684 Vippsnr 115851 | X11: 19.09.2025 | Y11: 209 | AA11: 86018570000 | AB11: NettBedrift betalingsformidling | AD11: 20.10.2025 | AE11: -120.05 | AG11: 89340400000 | AH11: NettBedrift betalingsformidling
B12: Misjonsløp | C12: =E12+D12 -> -32485.25 | D12: =Misjonsløp!C3 -> -32485.25 | Q12: 16.10.2025 | R12: 135 | S12: Drottningborgrussen | T12: 234408 | U12: Utb. 2000695 Vippsnr 115851 | X12: 20.10.2025 | Y12: 130 | Z12: Harrald Husby | AA12: 45035890000 | AB12: Til: Harrald Husby mosjonsløp krbabpizza premie | AD12: 23.10.2025 | AE12: -1316.8 | AF12: . | AG12: 94483110000 | AH12: Til: . Bakerussen ingrediensinkjøp 1 v3
B13: Kjøring | C13: =E13+D13 -> -660 | D13: =SUM(Kjøregodtgjørelse!S4:S14) -> -660 | Q13: 16.09.2025 | R13: 224 | S13: Drottningborgrussen | T13: 1169644 | U13: Utb. 2000683 Vippsnr 115851 | X13: 20.10.2025 | Y13: 121 | AA13: 89340400000 | AB13: NettBedrift betalingsformidling | AD13: 28.10.2025 | AE13: -119 | AF13: Vegard Straume Kleven | AG13: 37873160000 | AH13: Til: Vegard Straume Kleven natcupp gaffa teip
B14: Barista | C14: =E14+D14 -> -1566.95 | D14: =Barrista!D4 -> -2263.95 | E14: =Barrista!D5 -> 697 | Q14: 14.10.2025 | R14: 151 | S14: Drottningborgrussen | T14: 1556212 | U14: Utb. 2000694 Vippsnr 115851 | X14: 21.10.2025 | Y14: 112 | Z14: Drottningborgrussen | AA14: 969655 | AB14: Karoline Nepstad | AD14: 30.09.2025 | AE14: -52.5 | AH14: OCR-GIRO MÅNEDSAVGIFT 1 TRANS(ER) TYPE 438 763
B15: Nattcup | C15: =E15+D15 -> -3570.8 | D15: =Nattcup!D4 -> -6502.8 | E15: =Nattcup!D5 -> 2932 | Q15: 14.10.2025 | R15: 156 | S15: Drottningborgrussen | T15: 1555163 | U15: Utb. 2000693 Vippsnr 115851 | X15: 21.10.2025 | Y15: 117 | Z15: Drottningborgrussen | AA15: 878329 | AB15: 16741620661 | AD15: 30.09.2025 | AE15: -11.9 | AH15: TRANSAVG INNLØSNING BANKAXEPT 92 TRANS(ER) TYPE 438 751
B16: bokbind | C16: =E16+D16 -> 10977.66 | E16: 10977.66 | Q16: 13.10.2025 | R16: 158 | S16: Drottningborgrussen | T16: 1438142 | U16: Utb. 2000692 Vippsnr 115851 | X16: 21.10.2025 | Y16: 120 | Z16: Drottningborgrussen | AA16: 159950 | AB16: Innbetaling | AD16: 31.08.2025 | AE16: -52.5 | AH16: OCR-GIRO MÅNEDSAVGIFT 1 TRANS(ER) TYPE 438 763
Q17: 10.10.2025 | R17: 168 | S17: Drottningborgrussen | T17: 1362518 | U17: Utb. 2000691 Vippsnr 115851 | X17: 21.10.2025 | Y17: 102 | Z17: Drottningborgrussen | AA17: 112621 | AB17: 167400609126
B18: Drottningborgrussen | C18: =E18+D18 -> 3240 | D18: =M5 -> 0 | E18: =O8 -> 3240 | Q18: 10.09.2025 | R18: 242 | S18: Drottningborgrussen | T18: 708562 | U18: Utb. 2000681 Vippsnr 115851 | X18: 21.10.2025 | Y18: 111 | Z18: Drottningborgrussen | AA18: 833661 | AB18: Innbetaling
B19: Ukjent | C19: =E19+D19 -> 4782.25 | D19: =AE3 -> -1672.75 | E19: =Y3 -> 6455 | Q19: 10.09.2025 | R19: 245 | S19: Drottningborgrussen | T19: 708536 | U19: Utb. 2000682 Vippsnr 115851 | X19: 21.10.2025 | Y19: 108 | Z19: Drottningborgrussen | AA19: 377693 | AB19: Mosjonsløp, Jakob Erikstein
Q20: 08.10.2025 | R20: 174 | S20: Drottningborgrussen | T20: 1173563 | U20: Utb. 2000690 Vippsnr 115851 | X20: 21.10.2025 | Y20: 103 | Z20: Drottningborgrussen | AA20: 239115 | AB20: 16741696964
B21: sum | C21: =D21+E21+C2 -> -1492857.1 | D21: =SUM(D3:D19) -> -1579512.7 | E21: =SUM(E4:E19) -> 44007.66 | Q21: 02.09.2025 | R21: 259 | S21: Drottningborgrussen | T21: 192719 | U21: Utb. 2000680 Vippsnr 115851 | X21: 21.10.2025 | Y21: 107 | Z21: Drottningborgrussen | AA21: 1964 | AB21: .
D22: -1580830.4 | E22: 40755 | X22: 21.10.2025 | Y22: 99 | Z22: Drottningborgrussen | AA22: 4604 | AB22: 167992060993
D23: =D21-D22 -> 1317.65 | E23: =E21-E22 -> 3252.66 | X23: 21.10.2025 | Y23: 98 | Z23: Drottningborgrussen | AA23: 8021956835
X24: 21.10.2025 | Y24: 116 | Z24: Drottningborgrussen | AA24: 8021974574
X25: 21.10.2025 | Y25: 118 | Z25: Drottningborgrussen | AA25: 8021940906
A26: Estimert konto | C26: =SUM(C2:C20) -> -1492857.1 | D26: 796643.37 | E26: =C26-D26 -> -2289500.4 | X26: 21.10.2025 | Y26: 104 | Z26: Drottningborgrussen | AA26: 3097044239 | AB26: 16795923910
A27: på konto | C27: 265722 | X27: 22.10.2025 | Y27: 92 | Z27: Drottningborgrussen | AA27: 3097303040 | AB27: 197909859875
A28: Differanse | C28: =C27-C26 -> 1758579.1 | X28: 22.10.2025 | Y28: 87 | Z28: Drottningborgrussen | AA28: 683 | AB28: 167453731041
X29: 22.10.2025 | Y29: 88 | Z29: Drottningborgrussen | AA29: 8022113608
X30: 22.10.2025 | Y30: 90 | Z30: Drottningborgrussen | AA30: 8022919540
X31: 22.10.2025 | Y31: 93 | Z31: Drottningborgrussen | AA31: 8022935214
X32: 22.10.2025 | Y32: 95 | Z32: Drottningborgrussen | AA32: 8022992299
X33: 22.10.2025 | Y33: 96 | Z33: Drottningborgrussen | AA33: 8022904938
X34: 23.10.2025 | Y34: 85 | Z34: Drottningborgrussen | AA34: 385738 | AB34: 16791175512
X35: 23.10.2025 | Y35: 76 | Z35: Drottningborgrussen | AA35: 315575 | AB35: Innbetaling
X36: 23.10.2025 | Y36: 72 | Z36: . | AA36: 94483110000 | AB36: Til: . Bakerussen ingrediensinkjøp 1 v3
X37: 23.10.2025 | Y37: 79 | Z37: Drottningborgrussen | AA37: 3319 | AB37: .
X38: 23.10.2025 | Y38: 84 | Z38: Drottningborgrussen | AA38: 892848 | AB38: 1679 11 850417
X39: 23.10.2025 | Y39: 74 | Z39: Drottningborgrussen | AA39: 8023113140
X40: 23.10.2025 | Y40: 75 | Z40: Drottningborgrussen | AA40: 8023950498
...

Sheet Master kiosk
B1: ='Inn Kiosk'!A1 -> 0 | C1: {=#REF!} -> #REF! | D1: ='Inn Kiosk'!B1 -> 0 | E1: ='Inn Kiosk'!C1 -> 0 | F1: Totalt estimert kioskpris | G1: Antall Solgt | H1: Total pris | I1: Svinn | J1: svinsum | K1: På lager | L1: Nåværende overskudd | M1: Lagerverdi | N1: korreksjon | P1: Profitt | Q1: Prosent | R1: Vipps | S1: vipps total
B2: {=#REF!} -> #REF! | C2: #REF! | D2: {=#REF!} -> #REF! | E2: #REF! | F2: =C2*D2 -> #REF! | G2: =#REF! -> #REF! | H2: =#REF! -> #REF! | I2: 1 | J2: =I2*C2 -> #REF! | K2: =D2-G2-I2 -> #REF! | L2: =H2-E2 -> #REF! | M2: =K2*C2 -> #REF! | P2: =(F2-E2-R2)/D2 -> #REF! | Q2: =(F2-E2-F2*0.0225)/F2 -> #REF! | R2: =C2*0.0175 -> #REF! | S2: =F2*0.0175 -> #REF!
A3: Energidrikk | B3: #REF! | C3: #REF! | D3: #REF! | E3: #REF! | F3: =C3*D3 -> #REF! | G3: =#REF! -> #REF! | H3: =#REF! -> #REF! | I3: 1 | J3: =I3*C3 -> #REF! | K3: =D3-G3-I3 -> #REF! | L3: =H3-E3 -> #REF! | M3: =K3*C3 -> #REF! | P3: =(F3-E3-R3)/D3 -> #REF! | Q3: =(F3-E3-F3*0.0225)/F3 -> #REF! | R3: =C3*0.0175 -> #REF! | S3: =F3*0.0175 -> #REF! | Y3: Gevinster
B4: #REF! | C4: #REF! | D4: #REF! | E4: #REF! | F4: =C4*D4 -> #REF! | G4: =#REF! -> #REF! | H4: =#REF! -> #REF! | I4: -3 | J4: =I4*C4 -> #REF! | K4: =D4-G4-I4 -> #REF! | L4: =H4-E4 -> #REF! | M4: =K4*C4 -> #REF! | P4: =(F4-E4-R4)/D4 -> #REF! | Q4: =(F4-E4-F4*0.0225)/F4 -> #REF! | R4: =C4*0.0175 -> #REF! | S4: =F4*0.0175 -> #REF! | Y4: Monster monarch
B5: #REF! | C5: #REF! | D5: #REF! | E5: #REF! | F5: =C5*D5 -> #REF! | G5: =#REF! -> #REF! | H5: =#REF! -> #REF! | I5: 3 | J5: =I5*C5 -> #REF! | K5: =D5-G5-I5 -> #REF! | L5: =H5-E5 -> #REF! | M5: =K5*C5 -> #REF! | P5: =(F5-E5-R5)/D5 -> #REF! | Q5: =(F5-E5-F5*0.0225)/F5 -> #REF! | R5: =C5*0.0175 -> #REF! | S5: =F5*0.0175 -> #REF! | Y5: peach -> | Z5: fresh
B6: #REF! | C6: #REF! | D6: #REF! | E6: #REF! | F6: =C6*D6 -> #REF! | G6: =#REF! -> #REF! | H6: =#REF! -> #REF! | I6: -3 | J6: =I6*C6 -> #REF! | K6: =D6-G6-I6 -> #REF! | L6: =H6-E6 -> #REF! | M6: =K6*C6 -> #REF! | P6: =(F6-E6-R6)/D6 -> #REF! | Q6: =(F6-E6-F6*0.0225)/F6 -> #REF! | R6: =C6*0.0175 -> #REF! | S6: =F6*0.0175 -> #REF!
B7: #REF! | C7: #REF! | D7: #REF! | E7: #REF! | F7: =C7*D7 -> #REF! | G7: =#REF! -> #REF! | H7: =#REF! -> #REF! | I7: 5 | J7: =I7*C7 -> #REF! | K7: =D7-G7-I7 -> #REF! | L7: =H7-E7 -> #REF! | M7: =K7*C7 -> #REF! | P7: =(F7-E7-R7)/D7 -> #REF! | Q7: =(F7-E7-F7*0.0225)/F7 -> #REF! | R7: =C7*0.0175 -> #REF! | S7: =F7*0.0175 -> #REF!
B8: #REF! | C8: #REF! | D8: #REF! | E8: #REF! | F8: =C8*D8 -> #REF! | G8: =#REF! -> #REF! | H8: =#REF! -> #REF! | I8: 1 | J8: =I8*C8 -> #REF! | K8: =D8-G8-I8 -> #REF! | L8: =H8-E8 -> #REF! | M8: =K8*C8 -> #REF! | P8: =(F8-E8-R8)/D8 -> #REF! | Q8: =(F8-E8-F8*0.0225)/F8 -> #REF! | R8: =C8*0.0175 -> #REF! | S8: =F8*0.0175 -> #REF!
B9: #REF! | C9: #REF! | D9: #REF! | E9: #REF! | F9: =C9*D9 -> #REF! | G9: =#REF! -> #REF! | H9: =#REF! -> #REF! | I9: 4 | J9: =I9*C9 -> #REF! | K9: =D9-G9-I9 -> #REF! | L9: =H9-E9 -> #REF! | M9: =K9*C9 -> #REF! | P9: =(F9-E9-R9)/D9 -> #REF! | Q9: =(F9-E9-F9*0.0225)/F9 -> #REF! | R9: =C9*0.0175 -> #REF! | S9: =F9*0.0175 -> #REF!
B10: #REF! | C10: #REF! | D10: #REF! | E10: #REF! | F10: =C10*D10 -> #REF! | G10: =#REF! -> #REF! | H10: =#REF! -> #REF! | I10: -5 | J10: =I10*C10 -> #REF! | K10: =D10-G10-I10 -> #REF! | L10: =H10-E10 -> #REF! | M10: =K10*C10 -> #REF! | P10: =(F10-E10-R10)/D10 -> #REF! | Q10: =(F10-E10-F10*0.0225)/F10 -> #REF! | R10: =C10*0.0175 -> #REF! | S10: =F10*0.0175 -> #REF!
B11: #REF! | C11: #REF! | D11: #REF! | E11: #REF! | F11: =C11*D11 -> #REF! | G11: =#REF! -> #REF! | H11: =#REF! -> #REF! | I11: 2 | J11: =I11*C11 -> #REF! | K11: =D11-G11-I11 -> #REF! | L11: =H11-E11 -> #REF! | M11: =K11*C11 -> #REF! | P11: =(F11-E11-R11)/D11 -> #REF! | Q11: =(F11-E11-F11*0.0225)/F11 -> #REF! | R11: =C11*0.0175 -> #REF! | S11: =F11*0.0175 -> #REF!
B12: #REF! | C12: #REF! | D12: #REF! | E12: #REF! | F12: =C12*D12 -> #REF! | G12: =#REF! -> #REF! | H12: =#REF! -> #REF! | I12: 1 | J12: =I12*C12 -> #REF! | K12: =D12-G12-I12 -> #REF! | L12: =H12-E12 -> #REF! | M12: =K12*C12 -> #REF! | P12: =(F12-E12-R12)/D12 -> #REF! | Q12: =(F12-E12-F12*0.0225)/F12 -> #REF! | R12: =C12*0.0175 -> #REF! | S12: =F12*0.0175 -> #REF!
B13: #REF! | C13: #REF! | D13: #REF! | E13: #REF! | F13: =C13*D13 -> #REF! | G13: =#REF! -> #REF! | H13: =#REF! -> #REF! | I13: 0 | J13: =I13*C13 -> #REF! | K13: =D13-G13-I13 -> #REF! | L13: =H13-E13 -> #REF! | M13: =K13*C13 -> #REF! | P13: =(F13-E13-R13)/D13 -> #REF! | Q13: =(F13-E13-F13*0.0225)/F13 -> #REF! | R13: =C13*0.0175 -> #REF! | S13: =F13*0.0175 -> #REF!
B14: #REF! | C14: #REF! | D14: #REF! | E14: #REF! | F14: =C14*D14 -> #REF! | G14: =#REF! -> #REF! | H14: =#REF! -> #REF! | I14: 3 | J14: =I14*C14 -> #REF! | K14: =D14-G14-I14 -> #REF! | L14: =H14-E14 -> #REF! | M14: =K14*C14 -> #REF! | P14: =(F14-E14-R14)/D14 -> #REF! | Q14: =(F14-E14-F14*0.0225)/F14 -> #REF! | R14: =C14*0.0175 -> #REF! | S14: =F14*0.0175 -> #REF!
B15: #REF! | C15: #REF! | D15: #REF! | E15: #REF! | F15: =C15*D15 -> #REF! | G15: =#REF! -> #REF! | H15: =#REF! -> #REF! | I15: 28 | J15: =I15*C15 -> #REF! | K15: =D15-G15-I15 -> #REF! | L15: =H15-E15 -> #REF! | M15: =K15*C15 -> #REF! | P15: =(F15-E15-R15)/D15 -> #REF! | Q15: =(F15-E15-F15*0.0225)/F15 -> #REF! | R15: =C15*0.0175 -> #REF! | S15: =F15*0.0175 -> #REF!
B16: #REF! | C16: #REF! | D16: #REF! | E16: #REF! | F16: =C16*D16 -> #REF! | G16: =#REF! -> #REF! | H16: =#REF! -> #REF! | I16: -23 | J16: =I16*C16 -> #REF! | K16: =D16-G16-I16 -> #REF! | L16: =H16-E16 -> #REF! | M16: =K16*C16 -> #REF! | P16: =(F16-E16-R16)/D16 -> #REF! | Q16: =(F16-E16-F16*0.0225)/F16 -> #REF! | R16: =C16*0.0175 -> #REF! | S16: =F16*0.0175 -> #REF!
B17: #REF! | C17: #REF! | D17: #REF! | E17: #REF! | F17: =C17*D17 -> #REF! | G17: =#REF! -> #REF! | H17: =#REF! -> #REF! | I17: 1 | J17: =I17*C17 -> #REF! | K17: =D17-G17-I17 -> #REF! | L17: =H17-E17 -> #REF! | M17: =K17*C17 -> #REF! | P17: =(F17-E17-R17)/D17 -> #REF! | Q17: =(F17-E17-F17*0.0225)/F17 -> #REF! | R17: =C17*0.0175 -> #REF! | S17: =F17*0.0175 -> #REF!
... B19: #REF! | C19: #REF! | D19: #REF! | E19: #REF! | F19: =C19*D19 -> #REF! | G19: =#REF! -> #REF! | H19: =#REF! -> #REF! | I19: -6 | J19: =I19*C19 -> #REF! | K19: =D19-G19-I19 -> #REF! | L19: =H19-E19 -> #REF! | M19: =K19*C19 -> #REF! | P19: =(F19-E19-R19)/D19 -> #REF! | Q19: =(F19-E19-F19*0.0225)/F19 -> #REF! | R19: =C19*0.0175 -> #REF! | S19: =F19*0.0175 -> #REF!
B20: #REF! | C20: #REF! | D20: #REF! | E20: #REF! | F20: =C20*D20 -> #REF! | G20: =#REF! -> #REF! | H20: =#REF! -> #REF! | I20: 0 | J20: =I20*C20 -> #REF! | K20: =D20-G20-I23 -> #REF! | L20: =H20-E20 -> #REF! | M20: =K20*C20 -> #REF! | P20: =(F20-E20-R20)/D20 -> #REF! | Q20: =(F20-E20-F20*0.0225)/F20 -> #REF! | R20: =C20*0.0175 -> #REF! | S20: =F20*0.0175 -> #REF!
B21: #REF! | C21: #REF! | D21: #REF! | E21: #REF! | F21: =C21*D21 -> #REF! | G21: =#REF! -> #REF! | H21: =#REF! -> #REF! | I21: 0 | J21: =I21*C21 -> #REF! | K21: =D21-G21-I24 -> #REF! | L21: =H21-E21 -> #REF! | M21: =K21*C21 -> #REF! | P21: =(F21-E21-R21)/D21 -> #REF! | Q21: =(F21-E21-F21*0.0225)/F21 -> #REF! | R21: =C21*0.0175 -> #REF! | S21: =F21*0.0175 -> #REF!
B22: #REF! | C22: #REF! | D22: #REF! | E22: #REF! | F22: =C22*D22 -> #REF! | G22: =#REF! -> #REF! | H22: =#REF! -> #REF! | I22: 0 | J22: =I22*C22 -> #REF! | K22: =D22-G22-I25 -> #REF! | L22: =H22-E22 -> #REF! | M22: =K22*C22 -> #REF! | P22: =(F22-E22-R22)/D22 -> #REF! | Q22: =(F22-E22-F22*0.0225)/F22 -> #REF! | R22: =C22*0.0175 -> #REF! | S22: =F22*0.0175 -> #REF!
B23: #REF! | C23: #REF! | D23: #REF! | E23: #REF! | F23: =C23*D23 -> #REF! | G23: =#REF! -> #REF! | H23: =#REF! -> #REF! | I23: -2 | J23: =I23*C23 -> #REF! | K23: =D23-G23-I26 -> #REF! | L23: =H23-E23 -> #REF! | M23: =K23*C23 -> #REF! | P23: =(F23-E23-R23)/D23 -> #REF! | Q23: =(F23-E23-F23*0.0225)/F23 -> #REF! | R23: =C23*0.0175 -> #REF! | S23: =F23*0.0175 -> #REF!
B24: #REF! | C24: #REF! | D24: #REF! | E24: #REF! | F24: =C24*D24 -> #REF! | G24: =#REF! -> #REF! | H24: =#REF! -> #REF! | I24: 6 | J24: =I24*C24 -> #REF! | K24: =D24-G24-I27 -> #REF! | L24: =H24-E24 -> #REF! | M24: =K24*C24 -> #REF! | P24: =(F24-E24-R24)/D24 -> #REF! | Q24: =(F24-E24-F24*0.0225)/F24 -> #REF! | R24: =C24*0.0175 -> #REF! | S24: =F24*0.0175 -> #REF!
B25: #REF! | C25: #REF! | D25: #REF! | E25: #REF! | F25: =C25*D25 -> #REF! | G25: =#REF! -> #REF! | H25: =#REF! -> #REF! | I25: 12 | J25: =I25*C25 -> #REF! | K25: =D25-G25-I28 -> #REF! | L25: =H25-E25 -> #REF! | M25: =K25*C25 -> #REF! | P25: =(F25-E25-R25)/D25 -> #REF! | Q25: =(F25-E25-F25*0.0225)/F25 -> #REF! | R25: =C25*0.0175 -> #REF! | S25: =F25*0.0175 -> #REF!
B26: #REF! | C26: #REF! | D26: #REF! | E26: #REF! | F26: =C26*D26 -> #REF! | G26: =#REF! -> #REF! | H26: =#REF! -> #REF! | I26: 0 | J26: =I26*C26 -> #REF! | K26: =D26-G26-I29 -> #REF! | L26: =H26-E26 -> #REF! | M26: =K26*C26 -> #REF! | P26: =(F26-E26-R26)/D26 -> #REF! | Q26: =(F26-E26-F26*0.0225)/F26 -> #REF! | R26: =C26*0.0175 -> #REF! | S26: =F26*0.0175 -> #REF!
B27: #REF! | C27: #REF! | D27: #REF! | E27: #REF! | F27: =C27*D27 -> #REF! | G27: =#REF! -> #REF! | H27: =#REF! -> #REF! | I27: -5 | J27: =I27*C27 -> #REF! | K27: =D27-G27-I30 -> #REF! | L27: =H27-E27 -> #REF! | M27: =K27*C27 -> #REF! | P27: =(F27-E27-R27)/D27 -> #REF! | Q27: =(F27-E27-F27*0.0225)/F27 -> #REF! | R27: =C27*0.0175 -> #REF! | S27: =F27*0.0175 -> #REF!
B28: #REF! | C28: #REF! | D28: #REF! | E28: #REF! | F28: =C28*D28 -> #REF! | G28: =#REF! -> #REF! | H28: =#REF! -> #REF! | I28: -1 | J28: =I28*C28 -> #REF! | K28: =D28-G28-I31 -> #REF! | L28: =H28-E28 -> #REF! | M28: =K28*C28 -> #REF! | P28: =(F28-E28-R28)/D28 -> #REF! | Q28: =(F28-E28-F28*0.0225)/F28 -> #REF! | R28: =C28*0.0175 -> #REF! | S28: =F28*0.0175 -> #REF!
A29: Brus | B29: #REF! | C29: #REF! | D29: #REF! | E29: #REF! | F29: =C29*D29 -> #REF! | G29: =#REF! -> #REF! | H29: =#REF! -> #REF! | I29: 0 | J29: =I29*C29 -> #REF! | K29: =D29-G29-I32 -> #REF! | L29: =H29-E29 -> #REF! | M29: =K29*C29 -> #REF! | P29: =(F29-E29-R29)/D29 -> #REF! | Q29: =(F29-E29-F29*0.0225)/F29 -> #REF! | R29: =C29*0.0175 -> #REF! | S29: =F29*0.0175 -> #REF!
B30: #REF! | C30: #REF! | D30: #REF! | E30: #REF! | F30: =C30*D30 -> #REF! | G30: =#REF! -> #REF! | H30: =#REF! -> #REF! | I30: 1 | J30: =I30*C30 -> #REF! | K30: =D30-G30-I33 -> #REF! | L30: =H30-E30 -> #REF! | M30: =K30*C30 -> #REF! | P30: =(F30-E30-R30)/D30 -> #REF! | Q30: =(F30-E30-F30*0.0225)/F30 -> #REF! | R30: =C30*0.0175 -> #REF! | S30: =F30*0.0175 -> #REF!
B31: #REF! | C31: #REF! | D31: #REF! | E31: #REF! | F31: =C31*D31 -> #REF! | G31: =#REF! -> #REF! | H31: =#REF! -> #REF! | I31: 2 | J31: =I31*C31 -> #REF! | K31: =D31-G31-I34 -> #REF! | L31: =H31-E31 -> #REF! | M31: =K31*C31 -> #REF! | P31: =(F31-E31-R31)/D31 -> #REF! | Q31: =(F31-E31-F31*0.0225)/F31 -> #REF! | R31: =C31*0.0175 -> #REF! | S31: =F31*0.0175 -> #REF!
B32: #REF! | C32: #REF! | D32: #REF! | E32: #REF! | F32: =C32*D32 -> #REF! | G32: =#REF! -> #REF! | H32: =#REF! -> #REF! | I32: -1 | J32: =I32*C32 -> #REF! | K32: =D32-G32-I35 -> #REF! | L32: =H32-E32 -> #REF! | M32: =K32*C32 -> #REF! | P32: =(F32-E32-R32)/D32 -> #REF! | Q32: =(F32-E32-F32*0.0225)/F32 -> #REF! | R32: =C32*0.0175 -> #REF! | S32: =F32*0.0175 -> #REF!
B33: #REF! | C33: #REF! | D33: #REF! | E33: #REF! | F33: =C33*D33 -> #REF! | G33: =#REF! -> #REF! | H33: =#REF! -> #REF! | I33: 2 | J33: =I33*C33 -> #REF! | K33: =D33-G33-I36 -> #REF! | L33: =H33-E33 -> #REF! | M33: =K33*C33 -> #REF! | P33: =(F33-E33-R33)/D33 -> #REF! | Q33: =(F33-E33-F33*0.0225)/F33 -> #REF! | R33: =C33*0.0175 -> #REF! | S33: =F33*0.0175 -> #REF!
B34: #REF! | C34: #REF! | D34: #REF! | E34: #REF! | F34: =C34*D34 -> #REF! | G34: =#REF! -> #REF! | H34: =#REF! -> #REF! | I34: 0 | J34: =I34*C34 -> #REF! | K34: =D34-G34-I38 -> #REF! | L34: =H34-E34 -> #REF! | M34: =K34*C34 -> #REF! | P34: =(F34-E34-R34)/D34 -> #REF! | Q34: =(F34-E34-F34*0.0225)/F34 -> #REF! | R34: =C34*0.0175 -> #REF! | S34: =F34*0.0175 -> #REF!
B35: #REF! | C35: #REF! | D35: #REF! | E35: #REF! | F35: =C35*D35 -> #REF! | G35: =#REF! -> #REF! | H35: =#REF! -> #REF! | I35: -2 | J35: =I35*C35 -> #REF! | K35: =D35-G35-I39 -> #REF! | L35: =H35-E35 -> #REF! | M35: =K35*C35 -> #REF! | P35: =(F35-E35-R35)/D35 -> #REF! | Q35: =(F35-E35-F35*0.0225)/F35 -> #REF! | R35: =C35*0.0175 -> #REF! | S35: =F35*0.0175 -> #REF!
B36: #REF! | C36: #REF! | D36: #REF! | E36: #REF! | F36: =C36*D36 -> #REF! | G36: =#REF! -> #REF! | H36: =#REF! -> #REF! | I36: 4 | J36: =I36*C36 -> #REF! | K36: =D36-G36-I40 -> #REF! | L36: =H36-E36 -> #REF! | M36: =K36*C36 -> #REF! | P36: =(F36-E36-R36)/D36 -> #REF! | Q36: =(F36-E36-F36*0.0225)/F36 -> #REF! | R36: =C36*0.0175 -> #REF! | S36: =F36*0.0175 -> #REF!
A37: Godteri | B37: #REF! | C37: #REF! | D37: #REF! | E37: #REF! | F37: =C37*D37 -> #REF! | G37: =#REF! -> #REF! | H37: =#REF! -> #REF! | I37: 0 | J37: =I37*C37 -> #REF! | K37: =D37-G37-I41 -> #REF! | L37: =H37-E37 -> #REF! | M37: =K37*C37 -> #REF! | P37: =(F37-E37-R37)/D37 -> #REF! | Q37: =(F37-E37-F37*0.0225)/F37 -> #REF! | R37: =C37*0.0175 -> #REF! | S37: =F37*0.0175 -> #REF!
B38: #REF! | C38: #REF! | D38: #REF! | E38: #REF! | F38: =C38*D38 -> #REF! | G38: =#REF! -> #REF! | H38: =#REF! -> #REF! | I38: 1 | J38: =I38*C38 -> #REF! | K38: =D38-G38-I42 -> #REF! | L38: =H38-E38 -> #REF! | M38: =K38*C38 -> #REF! | N38: 1 | P38: =(F38-E38-R38)/D38 -> #REF! | Q38: =(F38-E38-F38*0.0225)/F38 -> #REF! | R38: =C38*0.0175 -> #REF! | S38: =F38*0.0175 -> #REF!
B39: #REF! | C39: #REF! | D39: #REF! | E39: #REF! | F39: =C39*D39 -> #REF! | G39: =#REF! -> #REF! | H39: =#REF! -> #REF! | I39: -5 | J39: =I39*C39 -> #REF! | K39: =D39-G39-I43 -> #REF! | L39: =H39-E39 -> #REF! | M39: =K39*C39 -> #REF! | P39: =(F39-E39-R39)/D39 -> #REF! | Q39: =(F39-E39-F39*0.0225)/F39 -> #REF! | R39: =C39*0.0175 -> #REF! | S39: =F39*0.0175 -> #REF!
B40: #REF! | C40: #REF! | D40: #REF! | E40: #REF! | F40: =C40*D40 -> #REF! | G40: =#REF! -> #REF! | H40: =#REF! -> #REF! | I40: 0 | J40: =I40*C40 -> #REF! | K40: =D40-G40-I44 -> #REF! | L40: =H40-E40 -> #REF! | M40: =K40*C40 -> #REF! | P40: =(F40-E40-R40)/D40 -> #REF! | Q40: =(F40-E40-F40*0.0225)/F40 -> #REF! | R40: =C40*0.0175 -> #REF! | S40: =F40*0.0175 -> #REF!
B41: #REF! | C41: #REF! | D41: #REF! | E41: #REF! | F41: =C41*D41 -> #REF! | G41: =#REF! -> #REF! | H41: =#REF! -> #REF! | I41: -3 | J41: =I41*C41 -> #REF! | K41: =D41-G41-I45 -> #REF! | L41: =H41-E41 -> #REF! | M41: =K41*C41 -> #REF! | P41: =(F41-E41-R41)/D41 -> #REF! | Q41: =(F41-E41-F41*0.0225)/F41 -> #REF! | R41: =C41*0.0175 -> #REF! | S41: =F41*0.0175 -> #REF!
...

Sheet Inn Kiosk
A76: Ut bank | B76: =SUM(B82:B113) -> -128188.24 | N76: ukjent med feil | O76: 1150 | P76: =27+27+15 -> 69
A77: Differanse | B77: =B75-B76 -> 128188.24 | N77: sum | O77: =SUM(O73:O76) -> 1150 | P77: =SUM(P73:P76) -> 69 | V77: sum | W77: =SUM(W73:W76) -> 0
A80: Bankutskrifter
A81: Utført dato | B81: Beløp ut | C81: Mottakernavn | D81: Numref | E81: Melding/KID/Fakt.nr
A82: 20.10.2025 | B82: -8966.9 | C82: Johannes Sødal | D82: 45035860000 | E82: Til: Johannes Sødal Kioskens andel
A83: 14.10.2025 | B83: -2088 | C83: Viktor Aandstad | D83: 85429420000 | E83: Til: Viktor Aandstad Battery kiosk. Innkjøp 2 kvit 3
A84: 13.10.2025 | B84: -50000 | D84: 175694291 | E84: 10.10 STORCASH BARSTØLVEIEN KRISTIANSAND
A85: 12.08.2025 | B85: -32735 | C85: Viktor Aandstad | D85: 62748000000 | E85: Til: Viktor Aandstad Utlegg storcach russen
A86: 11.09.2025 | B86: -347.5 | C86: Viktor Aandstad | D86: 90089470000 | E86: Til: Viktor Aandstad Rema 1000 kioskinkjøp nr 2
A87: 11.09.2025 | B87: -1150 | C87: Ruth Linnea Erøy | D87: 90089480000 | E87: Til: Ruth Linnea Erøy Joker kiosk innkjøp nr 2
A88: 11.09.2025 | B88: -486.5 | C88: Viktor Aandstad | D88: 90089460000 | E88: Til: Viktor Aandstad Rema 100 kioskinkjøp nr 2
A89: 11.09.2025 | B89: -32414.34 | C89: Viktor Aandstad | D89: 90089450000 | E89: Til: Viktor Aandstad SC Kioskinnkjøp nr 2

Sheet Vippsutskrifter+ Kiosk
A66: Inn vipps | B66: =(C63+I59+#REF!)*0.925 -> #REF!
A67: Inn bank vipps | B67: =SUM(B77:B232) -> 13930
A68: Differanse | B68: =B66-'Vippsutskrifter+ Kiosk'!B67 -> #REF! | F68: 80856
F69: =113434*0.965 -> 109463.81
A75: Transaksjoner inn:
A76: Utført dato | B76: Beløp inn | C76: Mottakernavn | D76: Numref | E76: Melding/KID/Fakt.nr
A77: 31.08.2025 | B77: 265 | C77: Drottningborgrussen | D77: 1434591 | E77: Utb. 2001577 Vippsnr 126635
A78: 30.09.2025 | B78: 188 | C78: Drottningborgrussen | D78: 607955 | E78: Utb. 2000018 Vippsnr 126635
A79: 29.10.2025 | B79: 11 | C79: Drottningborgrussen | D79: 1029196 | E79: Utb. 2000041 Vippsnr 126635
A80: 29.09.2025 | B80: 191 | C80: Drottningborgrussen | D80: 476321 | E80: Utb. 2000017 Vippsnr 126635
A81: 28.10.2025 | B81: 33 | C81: Drottningborgrussen | D81: 941221 | E81: Utb. 2000039 Vippsnr 126635
A82: 28.10.2025 | B82: 36 | C82: Drottningborgrussen | D82: 941095 | E82: Utb. 2000038 Vippsnr 126635
A83: 28.10.2025 | B83: 26 | C83: Drottningborgrussen | D83: 941220 | E83: Utb. 2000040 Vippsnr 126635
A84: 28.08.2025 | B84: 267 | C84: Drottningborgrussen | D84: 1311596 | E84: Utb. 2001576 Vippsnr 126635
A85: 27.10.2025 | B85: 44 | C85: Drottningborgrussen | D85: 836512 | E85: Utb. 2000037 Vippsnr 126635
A86: 27.08.2025 | B86: 268 | C86: Drottningborgrussen | D86: 1194854 | E86: Utb. 2001575 Vippsnr 126635
A87: 26.09.2025 | B87: 192 | C87: Drottningborgrussen | D87: 392660 | E87: Utb. 2000016 Vippsnr 126635
A88: 26.08.2025 | B88: 269 | C88: Drottningborgrussen | D88: 1101019 | E88: Utb. 2001572 Vippsnr 126635
... A146: 01.09.2025 | B146: 262 | C146: Drottningborgrussen | D146: 1544831 | E146: Utb. 2001578 Vippsnr 126635

Sheet Terminalutskrifter
A1: Kolonne1 | B1: Kolonne2 | C1: Kolonne3 | D1: Kolonne4 | F1: Kolonne1 | G1: Kolonne2 | H1: Kolonne3 | I1: Kolonne4
A65: Inn logført | B65: =C62+H62 -> 0
A66: Inn bank | B66: =SUM(B71:B137) -> 2705 | D66: Dette tallet på ikke brukes, husker ikke hvorfor
A67: Diff | B67: =B65-B66 -> -2705
A69: Transaksjoner
A70: Utført dato | B70: Beløp inn | C70: Mottakernavn | D70: Numref | E70: Melding/KID/Fakt.nr
A71: 27.10.2025 | B71: 50 | C71: Drottningborgrussen | D71: 10141 | E71: DROTTNINGBORGRU DROTTNINGBO 769821
A72: 26.09.2025 | B72: 194 | C72: Drottningborgrussen | D72: 391661 | E72: Nets 0030 5351127
A73: 24.10.2025 | B73: 59 | C73: Drottningborgrussen | D73: 768485 | E73: Nets 0031 5351127
A74: 21.10.2025 | B74: 100 | C74: Drottningborgrussen | D74: 10140 | E74: DROTTNINGBORGRU DROTTNINGBO 769821
A75: 19.09.2025 | B75: 206 | C75: Drottningborgrussen | D75: 1450281 | E75: Nets 0029 5351127
A76: 18.09.2025 | B76: 212 | C76: Drottningborgrussen | D76: 10138 | E76: DROTTNINGBORGRU DROTTNINGBO 769821
A77: 15.09.2025 | B77: 229 | C77: Drottningborgrussen | D77: 10137 | E77: DROTTNINGBORGRU DROTTNINGBO 769821
A78: 12.09.2025 | B78: 234 | C78: Drottningborgrussen | D78: 988727 | E78: Nets 0028 5351127
A79: 10.09.2025 | B79: 246 | C79: Drottningborgrussen | D79: 10136 | E79: DROTTNINGBORGRU DROTTNINGBO 769821
A80: 09.10.2025 | B80: 169 | C80: Drottningborgrussen | D80: 10139 | E80: DROTTNINGBORGRU DROTTNINGBO 769821
A81: 09.09.2025 | B81: 248 | C81: Drottningborgrussen | D81: 10135 | E81: DROTTNINGBORGRU DROTTNINGBO 769821
A82: 08.09.2025 | B82: 250 | C82: Drottningborgrussen | D82: 10134 | E82: DROTTNINGBORGRU DROTTNINGBO 769821
... A84: 03.09.2025 | B84: 257 | C84: Drottningborgrussen | D84: 10133 | E84: DROTTNINGBORGRU DROTTNINGBO 769821

Sheet Kjøregodtgjørelse
A2: Oppsumert | D2: Privat | K2: Borgen Bilen | R2: Kontrolpanel | T2: Diff | U2: =SUM(S4:S10)+B5 -> 0
R3: Utført dato | S3: Beløp ut | T3: Mottakernavn | U3: Numref | V3: Melding/KID/Fakt.nr
A4: Type | B4: sum | D4: Etternavn | E4: Etternavn | F4: grunn | G4: sum | H4: kontonummer | I4: betalt | K4: Fornavn | L4: Etternavn | M4: grunn | N4: sum | O4: betalt | R4: 15.09.2025 | S4: -30 | T4: Ole Aasen | U4: 19204740000 | V4: Til: Ole Aasen Kjøring
A5: sum privat | B5: 660 | D5: Ruben | E5: Pettersen | F5: Kiosken | G5: 315,00 kr | H5: 30007202462 | I5: Ja | K5: Lars | L5: oyy | M5: Kiosken | N5: 405 | O5: Nei | R5: 03.09.2025 | S5: -315 | T5: Benjamin Gjøterud | U5: 57384120000 | V5: Til: Benjamin Gjøterud Kjøregodtgjørelse
A6: sum borgen bil | B6: 810 | D6: Benjamin | E6: Gjøtterud | F6: Kiosken | G6: 315,00 kr | H6: 30303937613 | I6: Ja | K6: Thea | L6: Wiig | M6: Kiosken | N6: 405 | O6: Nei | R6: 03.09.2025 | S6: -315 | T6: Ruben Pettersen | U6: 57384110000 | V6: Til: Ruben Pettersen Kjøregodtgjørelse
A7: Sum kjøregodtgjørelse | B7: 1 470,00 kr | D7: Ole | E7: Aasen | F7: Is/milkshake | G7: 30,00 kr | H7: 30005311655 | I7: Ja | N7: 0 | O7: Nei
G8: 0,00 kr | I8: Nei | N8: 0 | O8: Nei
G9: 0,00 kr | I9: Nei | N9: 0 | O9: Nei
I10: Nei | O10: Nei
I11: Nei | O11: Nei

Sheet Misjonsløp
A1: Utgifter
B3: Sum utgifter | C3: =SUM(B11:B21) -> -32485.25
B4: Sum intekter | C4: 0
B5: overskud | C5: =C3+C4 -> -32485.25
A10: Beskrivelse | B10: Beløp ut | C10: Mottakernavn | D10: Til konto | E10: Numref | F10: Utført dato | G10: Melding/KID/Fakt.nr | I10: Beløp inn | J10: Mottakernavn | K10: Til konto | L10: Numref | M10: Utført dato | N10: Melding/KID/Fakt.nr
C11: Drottningborgrussen | D11: 3000 31 24475 | E11: 996770 | F11: 27.10.2025 | G11: Misjonsløp
C12: Drottningborgrussen | D12: 3000 31 24475 | E12: 498 | F12: 27.10.2025 | G12: Misjonsløpet
C13: Drottningborgrussen | D13: 3000 31 24475 | E13: 907111 | F13: 21.10.2025 | G13: Misjonsløp Emma Sofie
C14: Drottningborgrussen | D14: 3000 31 24475 | E14: 101760 | F14: 21.10.2025 | G14: 167969132437, misjonsløp, johannes
C15: Drottningborgrussen | D15: 3000 31 24475 | E15: 202 | F15: 21.10.2025 | G15: Misjonsløp
B16: -2395 | C16: Våge Multimedia AS | D16: 3330 25 39826 | E16: 19204770000 | F16: 15.09.2025 | G16: Til: Våge Multimedia AS
B17: -12689 | C17: Lucas Stoveland | D17: 3132 50 09120 | E17: 22959020000 | F17: 06.10.2025 | G17: Til: Lucas Stoveland Iphone
B18: -5980 | C18: Lucas Stoveland | D18: 3132 50 09120 | E18: 22959030000 | F18: 06.10.2025 | G18: Til: Lucas Stoveland Airpods
B19: -556.25 | C19: Våge Multimedia AS | D19: 3330 25 39826 | E19: 22959010000 | F19: 06.10.2025 | G19: Til: Våge Multimedia AS
B20: -5990 | C20: Samuel Stoveland | D20: 3207 32 24194 | E20: 22959040000 | F20: 06.10.2025 | G20: Til: Samuel Stoveland Soundbox
B21: -4875 | C21: Våge Multimedia AS | D21: 3330 25 39826 | E21: 94480440000 | F21: 01.10.2025 | G21: Til: Våge Multimedia AS

Sheet Nattcup
C3: Oppsumering
C4: sum ut | D4: =SUM(D13:D38) -> -6502.8
C5: Intekter | D5: =SUM(K13:K91) -> 2932
C6: Overskudd | D6: =D4+D5 -> -3570.8
C11: Utgifter | J11: Intekter
C12: Utført dato | D12: Beløp ut | E12: Mottakernavn | F12: Numref | G12: Melding/KID/Fakt.nr | J12: Utført dato | K12: Beløp inn | L12: Mottakernavn | M12: Numref | N12: Melding/KID/Fakt.nr
C13: 28.10.2025 | D13: -903.8 | E13: Elise Schalla Haugsjå | F13: 39541100000 | G13: Til: Elise Schalla Haugsjå Nattcup kull, tennveske og fyrstikker | J13: 30.09.2025 | K13: 189 | L13: Drottningborgrussen | M13: 607955 | N13: Utb. 2000001 Vippsnr 26180
C14: 23.10.2025 | D14: -156 | E14: Ulrik Flåt | F14: 94483090000 | G14: Til: Ulrik Flåt nattcup fløyter | J14: 30.09.2025 | K14: 187 | L14: Drottningborgrussen | M14: 607968 | N14: Utb. 2000002 Vippsnr 26180
C15: 15.10.2025 | D15: -5443 | E15: Norah Lende | F15: 85523960000 | G15: Til: Norah Lende Drakter til nattcup | J15: 29.10.2025 | K15: 6 | L15: Drottningborgrussen | M15: 1029196 | N15: Utb. 2000025 Vippsnr 26180
J16: 28.10.2025 | K16: 39 | L16: Drottningborgrussen | M16: 941221 | N16: Utb. 2000023 Vippsnr 26180
J17: 28.10.2025 | K17: 14 | L17: Drottningborgrussen | M17: 941220 | N17: Utb. 2000024 Vippsnr 26180
J18: 28.10.2025 | K18: 38 | L18: Drottningborgrussen | M18: 941095 | N18: Utb. 2000022 Vippsnr 26180
J19: 27.10.2025 | K19: 55 | L19: Drottningborgrussen | M19: 836512 | N19: Utb. 2000021 Vippsnr 26180
J20: 24.10.2025 | K20: 60 | L20: Drottningborgrussen | M20: 770108 | N20: Utb. 2000020 Vippsnr 26180
J21: 23.10.2025 | K21: 78 | L21: Drottningborgrussen | M21: 672524 | N21: Utb. 2000019 Vippsnr 26180
J22: 22.10.2025 | K22: 91 | L22: Drottningborgrussen | M22: 596605 | N22: Utb. 2000018 Vippsnr 26180
J23: 21.10.2025 | K23: 97 | L23: Drottningborgrussen | M23: 517324 | N23: Utb. 2000015 Vippsnr 26180
J24: 21.10.2025 | K24: 115 | L24: Drottningborgrussen | M24: 517804 | N24: Utb. 2000016 Vippsnr 26180
J25: 21.10.2025 | K25: 119 | L25: Drottningborgrussen | M25: 517799 | N25: Utb. 2000017 Vippsnr 26180
J26: 20.10.2025 | K26: 124 | L26: Drottningborgrussen | M26: 414192 | N26: Utb. 2000014 Vippsnr 26180
J27: 17.10.2025 | K27: 134 | L27: Drottningborgrussen | M27: 339492 | N27: Utb. 2000013 Vippsnr 26180
... J37: 03.10.2025 | K37: 182 | L37: Drottningborgrussen | M37: 910158 | N37: Utb. 2000003 Vippsnr 26180

Sheet Basar
D3: Oppsumering
D4: sum ut | E4: =SUM(D14:D40) -> 0
D5: Intekter | E5: =SUM(K13:K50) -> 428
D6: Overskudd | E6: =E4+E5 -> 428
D11: Utgifter | K11: Intekter
C12: Utført dato | D12: Beløp ut | E12: Mottakernavn | F12: Numref | G12: Melding/KID/Fakt.nr | H12: Melding/KID/Fakt.nr | J12: Utført dato | K12: Beløp inn | L12: Mottakernavn | M12: Numref | N12: Melding/KID/Fakt.nr | O12: Melding/KID/Fakt.nr
J13: 19.09.2025 | K13: 208 | L13: Drottningborgrussen | M13: 1451924 | N13: Utb. 2000057 Vippsnr 625975
J14: 16.09.2025 | K14: 220 | L14: Drottningborgrussen | M14: 1169651 | N14: Utb. 2000056 Vippsnr 625975

Sheet Barrista
C3: Oppsumering
C4: sum ut | D4: =SUM(D13:D55) -> -2263.95
C5: Intekter | D5: =SUM(K13:K93) -> 697
C6: Overskudd | D6: =D4+D5 -> -1566.95
C11: Utgifter | J11: Intekter
C12: Utført dato | D12: Beløp ut | E12: Mottakernavn | F12: Numref | G12: Melding/KID/Fakt.nr | J12: Utført dato | K12: Beløp inn | L12: Mottakernavn | M12: Numref | N12: Melding/KID/Fakt.nr
C13: 28.10.2025 | D13: -242 | E13: Elise Schalla Haugsjå | F13: 39541090000 | G13: Til: Elise Schalla Haugsjå Barristarussen | J13: 29.10.2025 | K13: 10 | L13: Drottningborgrussen | M13: 1029118 | N13: Utb. 2000122 Vippsnr 834150
C14: 28.10.2025 | D14: -308.2 | E14: Mari Tangen Tolo | F14: 37873150000 | G14: Til: Mari Tangen Tolo Barristarussen ingredienser | J14: 28.10.2025 | K14: 22 | L14: Drottningborgrussen | M14: 941095 | N14: Utb. 2000120 Vippsnr 834150
C15: 23.10.2025 | D15: -982.78 | E15: Emma Sofie Løwe | F15: 94483100000 | G15: Til: Emma Sofie Løwe Barristarussen ingredienser | J15: 28.10.2025 | K15: 27 | L15: Drottningborgrussen | M15: 941218 | N15: Utb. 2000121 Vippsnr 834150
C16: 22.09.2025 | D16: -189.9 | E16: Ida Skaregrøm Eskedal | F16: 96985720000 | G16: Til: Ida Skaregrøm Eskedal Kvit 1 innkjøp 1 | J16: 28.10.2025 | K16: 31 | L16: Drottningborgrussen | M16: 941218 | N16: Utb. 2000119 Vippsnr 834150
C17: 22.09.2025 | D17: -117 | E17: Ida Skaregrøm Eskedal | F17: 96985730000 | G17: Til: Ida Skaregrøm Eskedal Kvit 2 innkjøp 1 | J17: 24.10.2025 | K17: 69 | L17: Drottningborgrussen | M17: 770103 | N17: Utb. 2000118 Vippsnr 834150
C18: 20.10.2025 | D18: -230.07 | E18: Johannes Sødal | F18: 45035870000 | G18: Til: Johannes Sødal Barristarusens andel | J18: 17.09.2025 | K18: 216 | L18: Drottningborgrussen | M18: 1276017 | N18: Utb. 2000115 Vippsnr 834150
C19: 14.10.2025 | D19: -194 | E19: Andreas Tveit | F19: 85429430000 | G19: Til: Andreas Tveit Barista, innkjøp 1. mangler kvit | J19: 14.10.2025 | K19: 157 | L19: Drottningborgrussen | M19: 1556211 | N19: Utb. 2000117 Vippsnr 834150
J20: 10.10.2025 | K20: 165 | L20: Drottningborgrussen | M20: 1363386 | N20: Utb. 2000116 Vippsnr 834150

Sheet Milkshake
C3: Oppsumering
C4: sum ut | D4: =SUM(D13:D144) -> -6475.89
C5: Intekter | D5: =SUM(K13:K38) -> 1018
C6: Overskudd | D6: =D4+D5 -> -5457.89
C11: Utgifter | J11: Intekter
C12: Utført dato | D12: Beløp ut | E12: Mottakernavn | F12: Numref | G12: Melding/KID/Fakt.nr | J12: Utført dato | K12: Beløp inn | L12: Mottakernavn | M12: Numref | N12: Melding/KID/Fakt.nr
C13: 28.10.2025 | D13: -2318.1 | F13: 37873170000 | G13: Til: Ånund Tveit milkshakerussen ingredienser inkjøp v4 | J13: 29.10.2025 | K13: 12 | L13: Drottningborgrussen | M13: 1029196 | N13: Utb. 2000031 Vippsnr 625974
C14: 28.10.2025 | D14: -499 | E14: Ånund Tveit | F14: 37873180000 | G14: Til: Ånund Tveit Milkshakerussen blender | J14: 28.10.2025 | K14: 19 | L14: Drottningborgrussen | M14: 941210 | N14: Utb. 2000030 Vippsnr 625974
C15: 23.10.2025 | D15: -50 | E15: Ånund Tveit | F15: 94483080000 | G15: Til: Ånund Tveit milkshakerussen, manglende til blender | J15: 28.10.2025 | K15: 30 | L15: Drottningborgrussen | M15: 941210 | N15: Utb. 2000029 Vippsnr 625974
C16: 22.09.2025 | D16: -186 | E16: Ole Aasen | F16: 96985710000 | G16: Til: Ole Aasen Retur | J16: 17.10.2025 | K16: 132 | L16: Drottningborgrussen | M16: 338604 | N16: Utb. 2000028 Vippsnr 625974
C17: 20.10.2025 | D17: -295.46 | E17: Johannes Sødal | F17: 45035880000 | G17: Til: Johannes Sødal Milkshakerussens andel | J17: 17.09.2025 | K17: 214 | L17: Drottningborgrussen | M17: 1275771 | N17: Utb. 2000026 Vippsnr 625974
C18: 20.10.2025 | D18: -449 | E18: Ånund Tveit | F18: 45035900000 | G18: Til: Ånund Tveit Milkshakeruss blender | J18: 16.09.2025 | K18: 222 | L18: Drottningborgrussen | M18: 1169652 | N18: Utb. 2000024 Vippsnr 625974
C19: 20.10.2025 | D19: -595.6 | E19: Ånund Tveit | F19: 45035910000 | G19: Til: Ånund Tveit Milkshakerussen ingredienser | J19: 16.09.2025 | K19: 223 | L19: Drottningborgrussen | M19: 1169651 | N19: Utb. 2000025 Vippsnr 625974
C20: 15.09.2025 | D20: -1153.03 | E20: Ole Aasen | F20: 19204750000 | G20: Til: Ole Aasen Milkshake innkjøp nr 1 | J20: 10.10.2025 | K20: 166 | L20: Drottningborgrussen | M20: 1363386 | N20: Utb. 2000027 Vippsnr 625974
C21: 14.10.2025 | D21: -80.8 | E21: Ole Aasen | F21: 85429450000 | G21: Til: Ole Aasen Milkshake kvit 5
C22: 14.10.2025 | D22: -419.9 | E22: Ole Aasen | F22: 85429460000 | G22: Til: Ole Aasen Milkshake kvit 6
C23: 14.10.2025 | D23: -429 | E23: Ole Aasen | F23: 85429440000 | G23: Til: Ole Aasen Milkshake kvit 4

Sheet Panteruss
C3: Oppsumering
C4: sum ut | D4: =SUM(K13:K30) -> 0
C5: Intekter | D5: =SUM(D13:D32) -> 261
C6: Overskudd | D6: =D4+D5 -> 261
C11: Intekter
C12: Utført dato | D12: Beløp inn | E12: Mottakernavn | F12: Numref | G12: Melding/KID/Fakt.nr | J12: Utført dato | K12: Beløp ut | L12: Mottakernavn | M12: Numref | N12: Melding/KID/Fakt.nr
C13: 28.10.2025 | D13: 28 | E13: Drottningborgrussen | F13: 533860 | G13: Pantepenger til misjonsprosjektet
C14: 22.10.2025 | D14: 89 | E14: Drottningborgrussen | F14: 905464 | G14: Panting
C15: 14.10.2025 | D15: 144 | E15: Drottningborgrussen | F15: 242304 | G15: Pantepenger

Sheet Isruss
C3: Oppsumering
C4: sum ut | D4: =SUM(D13:D156) -> -3917.85
C5: Intekter | D5: =SUM(K13:K53) -> 1100
C6: Overskudd | D6: =D4+D5 -> -2817.85
C11: Utgifter | J11: Intekter
C12: Utført dato | D12: Beløp ut | E12: Mottakernavn | F12: Numref | G12: Melding/KID/Fakt.nr | J12: Utført dato | K12: Beløp inn | L12: Mottakernavn | M12: Numref | N12: Melding/KID/Fakt.nr
C13: 27.10.2025 | D13: -1595.05 | E13: Carl Martin Linnebo | F13: 25926270000 | G13: Til: Carl Martin Linnebo Isrussen, penger vippset av Carl | J13: 28.10.2025 | K13: 17 | L13: Drottningborgrussen | M13: 941210 | N13: Utb. 2000136 Vippsnr 625973
C14: 20.10.2025 | D14: -1017.75 | E14: Carl Martin Linnebo | F14: 45035920000 | G14: Til: Carl Martin Linnebo Isruss innkjøp. Carl vippset | J14: 28.10.2025 | K14: 25 | L14: Drottningborgrussen | M14: 941210 | N14: Utb. 2000137 Vippsnr 625973
C15: 15.09.2025 | D15: -335.6 | E15: Ole Aasen | F15: 19204760000 | G15: Til: Ole Aasen Isruss innkjøp nr 1 | J15: 17.10.2025 | K15: 131 | L15: Drottningborgrussen | M15: 338604 | N15: Utb. 2000135 Vippsnr 625973
C16: 13.10.2025 | D16: -969.45 | E16: Carl Martin Linnebo | F16: 61013320000 | G16: Til: Carl Martin Linnebo Isruss. Penger ble vippset | J16: 17.09.2025 | K16: 213 | L16: Drottningborgrussen | M16: 1275771 | N16: Utb. 2000131 Vippsnr 625973
J17: 16.09.2025 | K17: 219 | L17: Drottningborgrussen | M17: 1169651 | N17: Utb. 2000130 Vippsnr 625973
J18: 14.10.2025 | K18: 155 | L18: Drottningborgrussen | M18: 1556215 | N18: Utb. 2000134 Vippsnr 625973
J19: 10.10.2025 | K19: 167 | L19: Drottningborgrussen | M19: 1363386 | N19: Utb. 2000133 Vippsnr 625973
J20: 08.10.2025 | K20: 173 | L20: Drottningborgrussen | M20: 1173633 | N20: Utb. 2000132 Vippsnr 625973
